Workbook

Sheet Form Serah Terima
B5: SERAH TERIMA FASILITAS PERUSAHAAN
C7: Yang bertandatangan dibawah ini :
C9: Nama | D9: : | E9: Achmad Batul
C10: Jabatan | D10: : | E10: IT Hardware & Infrastructure Staff'
C11: Departemen | D11: : | E11: IT
B13: Dalam hal ini bertindak untuk dan atas nama PT. Grahadhika Sarana Purnajati sesuai dengan kewenangan jabatannya yang selanjutnya disebut sebagai Pihak Pertama atau Yang Menyerahkan
C15: Nama | D15: : | E15: M. Syarifuddin
C16: Jabatan | D16: : | E16: HC Generalist Manager
C17: Departemen | D17: : | E17: HCGA Legal
C18: Alamat | D18: : | E18: Jl. M.H. Thamrin No.40, DR. Soetomo, Kec. Tegalsari, Surabaya, Jawa Timur 60264
C19: Dalam hal ini bertindak untuk dan atas nama dirinya sendiri sesuai dengan jabatan, yang selanjutnya disebut sebagai Pihak Kedua atau Yang Menerima.
B21: Bahwa untuk menunjang kinerja dari Pihak Kedua, maka dengan ini Pihak Pertama telah menyerahkan fasilitas perusahaan untuk digunakan oleh Pihak Kedua sesuai dengan data dibawah ini, antara Lain :
C22: 1. 1 (satu) Buah Laptop, dengan data spesifikasi sebagai berikut :
D24: a. | E24: Merek | F24: : | G24: LENOVO
D25: b. | E25: Type | F25: : | G25: Lenovo V14 G4 IRU
D26: c. | E26: Serial Number | F26: : | G26: PF510A15
D27: d. | E27: Processor | F27: : | G27: Core I5 13420H
D28: e. | E28: Storage | F28: : | G28: SSD 512GB
D29: f. | E29: RAM | F29: : | G29: 16 GB
D30: g. | E30: Ukuran Layar | F30: : | G30: 14 INC
D31: f. | E31: Sistem Operasi | F31: : | G31: Windows 11 Home SL
D32: g. | E32: Office | F32: : | G32: MS. OHS2024
C36: 2. Software Terinstall, antara lain :
D38: a. | E38: Avast Free Antivirus
D39: b. | E39: Google Chrome
D40: c. | E40: Anydesk
D41: d. | E41: Microsoft Edge
D42: e. | E42: Office 365 Bussiness
D43: f. | E43: Tight Vnc
C44: 3. Kelengkapan tambahan, antara lain :
D46: a. | E46: Charger
D47: b.
D48: c.
D49: d.
B52: Fasilitas tersebut diserahkan oleh Pihak Pertama kepada Pihak Kedua berkaitan dengan jabatannya sebagai HC Generalist Manager dengan dilakukannya serah terima ini maka berlaku beberapa hal yang harus diperhatikan, antara lain:
C54: 1. Bahwa Fasilitas perusahaan yang diterima oleh Pihak Kedua tidak diperbolehkan untuk dipindah tangankan dan atau dilakukan pengalihan fasilitas kepada orang lain selain dan tanpa adanya persetujuan atasan dan Persetujuan Pihak Pertama.
C56: 2. Bahwa Pihak Kedua bertanggung jawab secara penuh atas segala resiko yang terjadi dikarenakan timbulnya kerusakan dan atau kehilangan yang diakibatkan dari kelalaian Pihak Kedua yang dilakukan secara sengaja dan atau tidak sengaja selama penggunaan fasilitas tersebut. serta Pihak Kedua berkewajiban menanggung segala kerusakan secara pribadi seusai adanya pengecekan dari Pihak Pertama.
C58: 3. Bahwa Pihak Kedua bersedia dalam berjalannya waktu penggunaan fasilitas perusahaan tersebut, untuk dapat diperiksa dan atau dilakukannya audit terkait dengan isi dan dokumen yang ada dalam fasilitas tersebut.
C60: 4. Bahwa Pihak Kedua bertanggung Jawab secara penuh atas data, isi, konten dan dokumen yang berada didalam fasilitas perusahaan tersebut. Serta Pihak Kedua dilarang keras untuk menggunakan fasilitas perusahaan tersebut diluar kepentingan dan tujuan perusahaan yang dilakukan di dalam jam kerja maupun diluar jam kerja.
C62: 5. Apabila Pihak Kedua sudah tidak bekerja kembali dan atau mengundurkan diri. maka Pihak Kedua berkewajiban mengembalikan fasiltas perusahaan tersebut dalam keadaan baik sebagaimana mestinya.
...

Sheet Inventory History
A1: niam | B1: Tanggal | C1: Pemegang sebelumnya | D1: Pemegang sekarang | E1: Merk | F1: Type | G1: Serial Number | H1: Processor | I1: Storage | J1: RAM | K1: Ukuran Layar | L1: Sistem Operasi | M1: Office | N1: Catatan Khusus | O1: no aset mam
A2: Master --->> | B2: ='Form Serah Terima'!E66 -> 46155 | D2: ='Form Serah Terima'!E15 -> M. Syarifuddin | E2: ='Form Serah Terima'!G24 -> LENOVO | F2: ='Form Serah Terima'!G25 -> Lenovo V14 G4 IRU | G2: ='Form Serah Terima'!G26 -> PF510A15 | H2: ='Form Serah Terima'!G27 -> Core I5 13420H | I2: ='Form Serah Terima'!G28 -> SSD 512GB | J2: ='Form Serah Terima'!G29 -> 16 GB | K2: ='Form Serah Terima'!G30 -> 14 INC | L2: ='Form Serah Terima'!G31 -> Windows 11 Home SL | M2: ='Form Serah Terima'!G32 -> MS. OHS2024
A3: Marketing | B3: 44909 | C3: Hendra | D3: Fidel | E3: Lenovo | F3: LA201 | G3: 290830 | H3: Core i5 | I3: SSD 500GB | J3: 8GB | K3: 14 | L3: Windows 7 Pro | M3: MS Office | O3: IT/I/2025/0002
B4: 44909 | C4: James | D4: Adi Nugroho | E4: Acer | N4: di MKT | O4: IT/I/2025/0004
B5: 44909 | C5: James | D5: Dr Suci | E5: Macbook | F5: Air | G5: C02PP07CGFWN | H5: I5-1.6 Ghz | I5: SSD 250GB | J5: 4GB | K5: 11 Inch | L5: Monterey 12.7.4 | M5: ms Office | N5: di MA | O5: RnD/VIII/2024/0001
B6: 44909 | C6: Abram | D6: Gigih | E6: PC Dell | F6: Optiplex 7070 | G6: H0K8F13 | H6: i7-9700 | I6: SSD 500,HDD 1TB | J6: 16GB | K6: 32 | L6: Win 10 Pro | M6: 365 | O6: IT/I/2025/0003
B7: 44909 | C7: Agnes | D7: Adi Nugroho -> Caroline Widyasmara | E7: Dell | F7: Latitude 3400 | G7: F72SLT2 | H7: i5-8265U | I7: SSD 500 GB | J7: 8GB | K7: 14 | L7: Win 10 Pro | O7: IT/I/2025/0005
B8: 44909 | D8: Lili | E8: PC rakitan | F8: PC Rakitan | H8: i5-2500 | I8: SSD 500GB | J8: 16GB | K8: 24 | L8: Win 10 Pro | M8: 365 | O8: IT/I/2025/0006
B9: 45033 | C9: Farrah | D9: Adi Nugroho | E9: Lenovo | F9: V14 | G9: PF43QG7W | H9: Core(TM) i5-1135G7 @ 2.40GHz 2.42 GH | I9: SSD 500GB | J9: 8GB | K9: 14 Inch | L9: Win 11 | M9: Home Student | O9: IT/I/2025/0007
B10: 45118 | C10: Ayling Calista Azalia | D10: Suci Tri Puspitaningrum(Uchi) | E10: Lenovo | F10: IP 3-14IAU7 5NID | G10: PF450587 | H10: i5-1235U | I10: SSD 512GB nvme | J10: 8GB | K10: 14 Inch | L10: Win 11 | M10: 365 | O10: IT/I/2025/0008
B11: 45118 | D11: Monica Ayu Widyani | E11: Lenovo | F11: Lenovo Ideapad 3 14ABA7 | G11: PF3X3XXG | H11: AMD Ryzen 5 5000 | I11: SSD 512GB M2 NVME | J11: 8GB | K11: 14 Inch | L11: Win 10 Home | M11: 365 | O11: IT/I/2025/0009
B12: 45408 | C12: Farrah | D12: Nadia Aprilia Tas'an | E12: Lenovo | F12: IP 3-14IAU7 5NID | G12: PF450587 | H12: i5-1235U | I12: SSD 512GB nvme | J12: 8GB | K12: 14 Inch | L12: Win 11 | M12: 365 | O12: IT/I/2025/0010
B13: 45495 | C13: Agis | D13: Dicky Hendriyanto | E13: Lenovo | F13: K14 | G13: PF-3ARAZA | H13: i5 | I13: SSD 512GB | J13: 8GB | K13: 14" | L13: WIN 11 | M13: OHS | O13: IT/I/2025/0011
B14: 45722 | C14: laptop baru | D14: Suci Tri Puspitaningrum | E14: lenovo | F14: Ideapad 3 14IAU7 | G14: PF50RVE5 | H14: CORE I3-1215U | I14: SSD 512 GB | J14: 16 GB | K14: 14 Inch | L14: Windows 11 Home Single | M14: Office Student 2021 | O14: IT/I/2025/0012
B15: 45757 | C15: laptop baru | D15: Fidelia Marchella Nakamase | E15: lenovo | F15: LOQ 15IAX9 | G15: MP2Z0VDG | H15: Intel i5-12450HX | I15: SSD 512 GB | J15: 12 GB | K15: 15.6 Inch | L15: Windows 11 Home Single | M15: Office OHS | O15: IT/I/2025/0013
B16: 45763 | C16: ex Fidelia Marchella Nakamase | D16: Merlin Fransisca | E16: lenovo | F16: V14 G2 ALC | G16: PF3DE5DF | H16: AMD Ryzen 5 5500U | I16: SSD 512 GB | J16: 16 GB | K16: 14 Inch | L16: Windows 11 Home Single | M16: Office OHS | Q16: ditukar dengan caro
B17: 45825 | C17: Adi Nugroho | D17: Caroline Widyasmara | E17: Dell | F17: Latitude 3400 | G17: F72SLT2 | H17: i5-8265U | I17: SSD 500 GB | J17: 8GB | K17: 14 Inc | L17: Win 10 Pro | M17: MS. Office 365 Bussiness
B18: 45866 | C18: ex uchi CL | D18: Merlin Fransisca | E18: Lenovo | F18: IdeaPad 3 14IAU7 | G18: PF4RTBBN | H18: Core I3-1215U | I18: SSD512GB | J18: 16GB | K18: 14 INC | L18: Win 11 Home SL | M18: MS. Office 365 Bussiness
B19: 45866 | C19: ex merlin | D19: Claudia Florensia | E19: Lenovo | F19: Lemvo V14 G2 ALC | G19: PF3DE5DF | H19: AMD Ryzen 5 5500U | I19: SSD512GB | J19: 16GB | K19: 14 INC | L19: Win 11 Home SL | M19: MS. Office 365 Bussiness
A23: FAT | B23: 44909 | D23: Stela | E23: Lenovo | F23: IP 3-14ITL6 | G23: PF3SRGE7 | H23: i5-1135G7 | I23: SSD 512GB | J23: 8GB | K23: 14 | L23: Win 11 | M23: 365 | O23: IT/I/2025/0014
B24: 44909 | D24: Linda | E24: PC rakitan | F24: PC Rakitan | G24: - | H24: i3-3220 | I24: SSD 256GB | J24: 4GB | K24: 14 | L24: Win 7 Pro | M24: 365 | O24: IT/I/2025/0015
B25: 44909 | D25: Titi | E25: PC HP | F25: HP 280 G4 MT | G25: 8CG300BGS | H25: i5-8400 | I25: HDD 1TB | J25: 4GB | K25: 14 | L25: Win 10 Pro | M25: 365 | O25: IT/I/2025/0016
B26: 44909 | D26: Adelia | E26: Lenovo | F26: IP3-14IAU7 | G26: PF4Q008M | H26: i3-1215U | I26: SSD 512GB | J26: 8GB | K26: 14 | L26: Win 11 | M26: 365 | O26: IT/I/2025/0017
B27: 44909 | D27: Dewi | E27: Lenovo | F27: K14 | G27: PF-3ARAZA | H27: i5 | I27: SSD 512GB | J27: 8GB | K27: 14 | L27: WIN 11 | M27: 365 | O27: IT/I/2025/0018
B28: 44909 | D28: Della | E28: PC HP | F28: HP 280 G4 MT | G28: 8CG83218CD | H28: i5-8400 | I28: HDD 1TB | J28: 8GB | K28: 14 | L28: Win 10 Pro | M28: 365 | O28: IT/I/2025/0019
B29: 45048 | D29: Andreas Hermanto | E29: Dell | F29: Latitude 3480 | G29: CVS4MJ2 | H29: Core(TM) i5-7200U | I29: SSD 500GB | J29: 8GB | K29: 14 Inch | L29: Win 10 | M29: 365 | O29: IT/I/2025/0020
D30: Fitri | E30: HP | F30: HP 280 G4 MT | G30: 8CG3218FR | H30: i5-8400 | I30: SSD500GB | J30: 8GB | K30: 14 | L30: Win 10 Pro | M30: 365 | O30: IT/I/2025/0021
B31: =DATE(YYYY-M-DDB(B32)) -> #N/A | D31: Lily Permatasari | E31: Dell | F31: Latitude 3480 | G31: JVVQ3L2 | H31: i5-7200U | I31: SSD500GB | J31: 8GB | K31: 14 | L31: Win 10 Pro | M31: 365 | O31: IT/I/2025/0022
B32: 45679 | D32: Christina | E32: Lenovo | F32: V14 G4 IRU | G32: PF51DWB | H32: Intel Core i5-13420H | I32: SSD 512GB | J32: 16GB | K32: 14" | L32: Windows 11 Home | M32: Micrsoft office 365 | O32: IT/I/2025/0023
B33: 45883 | D33: Arief | E33: Lenovo | F33: IdeaPad Slim 3 14IRH10 | G33: PF59YJH0 | H33: Core I5 13420H | I33: SSD512GB | J33: 8GB | K33: 14 INC | L33: Win 11 Home SL | M33: MS. Office 365 Bussiness
B34: 46073 | D34: Titi Suparyanti | E34: Lenovo | F34: Ideapad Slim 3 14IRH10 | G34: PF5SWFBJ | H34: CORE I5-1315H | I34: SSD 512GB | J34: 16 gb | K34: 14 INC | L34: Win 11 Home SL | M34: MS. Office 365 Bussiness
B35: 46147 | D35: chyntia jati kusuma | E35: LENOVO | F35: Lenovo V14 G5 IRL | G35: PF5VYRZP | H35: Core I5 13420H | I35: SSD 512GB | J35: 16GB | K35: 14 INC | L35: Windows 11 Home SL | M35: MS. OHS2024
B36: 46148 | D36: AHMAD SEPTA RACHMAWAN | E36: LENOVO | F36: Lenovo V14 G5 IRL | G36: PF5W38SF | H36: Core I5 13420H | I36: SSD 512GB | J36: 8GB | K36: 14 INC | L36: Windows 11 Home SL | M36: MS. OHS2024
A37: MLG | B37: 45883 | D37: Wulan | E37: Lenovo | F37: IdeaPad Slim 3 14IRH10 | G37: PF59YLQB | H37: Core I5 13420H | I37: SSD512GB | J37: 8GB | K37: 14 INC | L37: Win 11 Home SL | M37: MS. Office 365 Bussiness
A41: RND | B41: 46037 | D41: dr. Andrea Budianto | E41: Lenovo | F41: Lenovo Ideapad 3 | G41: PF3AL1TM | H41: Ryzen 5 5500u | I41: SSD 256GB | J41: 8 gb | K41: 14 INC | L41: Win 11 Home SL | M41: MS. Office 365 Bussiness
B42: 46059 | D42: dr. Andrea Budianto | E42: Lenovo | F42: IDEAPAD 5 14ALC05-FXID | G42: MP27GMP3 | H42: R5-5500U | I42: SSD 512GB | J42: 8 gb | K42: 14 INC | L42: Win 11 Home SL | M42: MS. Office 365 Bussiness
B43: 46059 | D43: dr. Dewi Shinta Mayasari | E43: Lenovo | F43: Lenovo Ideapad 3 | G43: PF3AL1TM | H43: R5-5500U | I43: SSD 512GB | J43: 8 gb | K43: 14 INC | L43: Win 11 Home SL | M43: MS. Office 365 Bussiness
A45: CM | B45: 45985 | C45: CM MEDAN | D45: Nanda | E45: Dell | F45: Latitude 5290 | G45: 9TXPJR2 | H45: CORE I5-8250U | I45: SSD 512 GB | J45: 4 GB | K45: 14 INC | L45: Win 11 Home SL | M45: MS. Office 365 Bussiness
B46: 46140 | C46: CM CITRALAND | D46: Evi Diana Pertiwi | E46: LENOVO | F46: Ideapad 3 | G46: PF50RVE5 | H46: CORE I3-1215U | I46: SSD 512GB | J46: 16GB | K46: 14 INC | L46: Windows 11 Home SL | M46: MS. OHS2024
B47: 46140 | D47: Indah Nurhayati | E47: LENOVO | F47: Lenovo K14 Gen1 | G47: PF3VYR8 | H47: Core I5 1135G7 | I47: SSD 512GB | J47: 16GB | K47: 14 INC | L47: Windows 11 Home SL | M47: MS. OHS2024
...

Sheet Form Serah Terima Add On
B5: SERAH TERIMA FASILITAS PERUSAHAAN
C7: Yang bertandatangan dibawah ini :
C9: Nama | D9: : | E9: Muhammad Rizky Amin
C10: Jabatan | D10: : | E10: IT Generalist
C11: Departemen | D11: : | E11: IT
B13: Dalam hal ini bertindak untuk dan atas nama PT. Grahadhika Sarana Purnajati sesuai dengan kewenangan jabatannya yang selanjutnya disebut sebagai Pihak Pertama atau Yang Menyerahkan
C15: Nama | D15: : | E15: Evia Diana Pertiwi
C16: Jabatan | D16: : | E16: Clinic Manager
C17: Departemen | D17: : | E17: Miracle Citraland
C18: Alamat | D18: : | E18: Jl. Emerald Mansion Citraland No.TN1 / 17, Lidah Kulon, Kec. Lakarsantri, Surabaya, Jawa Timur 60213
C19: Dalam hal ini bertindak untuk dan atas nama dirinya sendiri sesuai dengan jabatan, yang selanjutnya disebut sebagai Pihak Kedua atau Yang Menerima.
B21: Bahwa untuk menunjang kinerja dari Pihak Kedua, maka dengan ini Pihak Pertama telah menyerahkan fasilitas perusahaan untuk digunakan oleh Pihak Kedua sesuai dengan data dibawah ini, antara Lain :
C22: 1. 1(satu) Buah Tablet PC, dengan data spesifikasi sebagai berikut :
D24: a. | E24: Merek | F24: : | G24: Samsung
D25: b. | E25: Type | F25: : | G25: Galaxy Tab S10 FE 5G SM-X526B
D26: c. | E26: Serial Number | F26: : | G26: 350703930025346
D27: d. | E27: Processor | F27: : | G27: -
D28: e. | E28: Storage | F28: : | G28: 128GB
D29: f. | E29: RAM | F29: : | G29: 8GB
D30: g. | E30: Ukuran Layar | F30: : | G30: 10inch
C32: 2. Software Terinstall, antara lain :
D34: a. | E34: -
D35: b. | E35: -
D36: c. | E36: -
C38: 3. Kelengkapan tambahan, antara lain :
D40: a. | E40: Kabel data
D41: b. | E41: Charger
D42: c. | E42: Flip Cover Keyboard
D43: d. | E43: Pencil
B47: Fasilitas tersebut diserahkan oleh Pihak Pertama kepada Pihak Kedua berkaitan dengan jabatannya sebagai Clinic Manager, dengan dilakukannya serah terima ini maka berlaku beberapa hal yang harus diperhatikan, antara lain:
C49: 1. Bahwa Fasilitas perusahaan yang diterima oleh Pihak Kedua tidak diperbolehkan untuk dipindah tangankan dan atau dilakukan pengalihan fasilitas kepada orang lain selain dan tanpa adanya persetujuan atasan dan Persetujuan Pihak Pertama.
C51: 2. Bahwa Pihak Kedua bertanggung jawab secara penuh atas segala resiko yang terjadi dikarenakan timbulnya kerusakan dan atau kehilangan yang diakibatkan dari kelalaian Pihak Kedua yang dilakukan secara sengaja dan atau tidak sengaja selama penggunaan fasilitas tersebut. serta Pihak Kedua berkewajiban menanggung segala kerusakan secara pribadi seusai adanya pengecekan dari Pihak Pertama.
C53: 3. Bahwa Pihak Kedua bersedia dalam berjalannya waktu penggunaan fasilitas perusahaan tersebut, untuk dapat diperiksa dan atau dilakukannya audit terkait dengan isi dan dokumen yang ada dalam fasilitas tersebut.
C55: 4. Bahwa Pihak Kedua bertanggung Jawab secara penuh atas data, isi, konten dan dokumen yang berada didalam fasilitas perusahaan tersebut. Serta Pihak Kedua dilarang keras untuk menggunakan fasilitas perusahaan tersebut diluar kepentingan dan tujuan perusahaan yang dilakukan di dalam jam kerja maupun diluar jam kerja.
C57: 5. Apabila Pihak Kedua sudah tidak bekerja kembali dan atau mengundurkan diri. maka Pihak Kedua berkewajiban mengembalikan fasiltas perusahaan tersebut dalam keadaan baik sebagaimana mestinya.
B59: Demikian serah terima fasilitas perusahaan ini dibuat dan disetujui oleh PARA PIHAK dan menjadi hukum yang dapat dipertanggung jawabkan dikemudian hari.
B61: Surabaya, | E61: 46083
C63: Mengetahui, | G63: Menyetujui,
B67: (_____________) | D67: (_____________) | G67: (_____________) (_____________)
B68: Departemen IT | D68: Departemen Head | G68: HRD - Personalia Penerima

Sheet Inventory History Add On
A1: wh | B1: Tanggal | C1: Pemegang sebelumnya | D1: Pemegang sekarang | E1: Merk | F1: Type | G1: Serial Number | H1: Processor | I1: Storage | J1: RAM | K1: Ukuran Layar | L1: Sistem Operasi | M1: Office | N1: Catatan Khusus
A2: Master --->> | B2: ='Form Serah Terima Add On'!E61 -> 46083 | D2: ='Form Serah Terima Add On'!E15 -> Evia Diana Pertiwi | E2: ='Form Serah Terima Add On'!G24 -> Samsung | F2: ='Form Serah Terima Add On'!G25 -> Galaxy Tab S10 FE 5G SM-X526B | G2: ='Form Serah Terima Add On'!G26 -> 350703930025346 | H2: ='Form Serah Terima Add On'!G27 -> - | I2: ='Form Serah Terima Add On'!G28 -> 128GB | J2: ='Form Serah Terima Add On'!G29 -> 8GB | K2: ='Form Serah Terima Add On'!G30 -> 10inch | L2: ='Form Serah Terima Add On'!E34 -> - | M2: ='Form Serah Terima Add On'!E35 -> -
A3: Corporate
B8: 45470 | D8: Nadia Aprilia Tas'an | E8: Apple | F8: iPad | G8: DMPCV8KSLM93 | H8: - | I8: 64GB | J8: - | K8: - | L8: - | M8: -
B9: 45776 | D9: Dewa | E9: Infinix | F9: #REF! | G9: 355477771893162 | H9: Helio G1000 | I9: 256 Gb | J9: 16Gb | K9: 6.78 | L9: - | M9: -
B11: 45044 | C11: Ragil Bayu Respati | D11: Rahayu Kibtiani | E11: OPPO | F11: A74 | G11: 211703fe | H11: Snapdragon 662 | I11: 128GB | J11: 6GB | K11: 6.43" | L11: - | M11: - | N11: skrng dipakai mbak Ayu Corp
B12: 45044 | D12: Rahayu Kibtiani | E12: OPPO | F12: A74 | G12: 211703fe | H12: Snapdragon 662 | I12: 128GB | J12: 6GB | K12: 6.43" | L12: - | M12: -
A14: Thamrin
B15: 44985 | D15: Evi Diana Pertiwi | E15: Oppo | F15: Reno8 T 4G | G15: FU4PRWDAKFY9Z90N | H15: MediaTek Helio G99 | I15: 8GB | J15: 256GB | K15: 6,43 inci | L15: - | M15: - | N15: CRO
B16: 44985 | D16: Evi Diana Pertiwi | E16: Oppo | F16: Reno8 T 4G | G16: N7TCJRV4BY5XCYLN | H16: MediaTek Helio G99 | I16: 8GB | J16: 256GB | K16: 6,43 inci | L16: - | M16: - | N16: MEDICARE
B17: 45341 | D17: Evia Diana | E17: WLN | F17: M200 KD-C100U | H17: - | J17: - | K17: - | L17: - | M17: -
B18: 45735 | D18: Suci Tri Puspitaningrum | E18: Apple | F18: iPad Gen 9 | G18: KFWH4MFML6 | H18: - | I18: 64GB | K18: 10.2" | L18: - | M18: -
B19: 45772 | D19: Fidelia Marchella Nakamase | E19: SEAGATE EXPANSION HDD | F19: SRD0NF1 | G19: NT1ACJW7 | H19: - | I19: 1TB | L19: - | M19: -
B20: 45988 | D20: Fenty Indria | E20: Seagate | F20: Expansion | G20: - | H20: - | I20: 1 TB | J20: - | K20: - | L20: - | M20: -
A21: RnD | B21: 45889 | D21: Alinda Rahmani | E21: Ugreen | F21: SSD Samsung Evo | G21: - | H21: - | I21: 500GB | J21: - | K21: - | N21: diserahkan ke dr Shinta
A23: Citraland | B23: 44974 | D23: Indah Nurhayati | E23: Oppo | F23: Reno8 T 4G | G23: A6PJ9HX09LGUFYKB | H23: MediaTek Helio G99 | I23: 8GB | J23: 256GB | K23: 6,43 inci | L23: - | M23: -
B24: 45491 | D24: Suci Tri Puspitaningrum | E24: Oppo | F24: Reno 11 F | G24: QFAZLGM5PI7NRDE | H24: - | I24: 256GB | J24: 8GB | K24: - | L24: - | M24: -
B25: 45537 | D25: Tjoa Liiy Phing | E25: Apple | F25: iPad Gen 9 | G25: MQPH4274CC | H25: A13 Bionic | I25: 256GB | K25: 45332
A26: TP | B26: 44974 | D26: Indah Nurhayati | E26: Oppo | F26: Reno8 T 4G | G26: A6PJ9HX09LGUFYKB | H26: MediaTek Helio G99 | I26: 8GB | J26: 256GB | K26: 6,43 inci | L26: - | M26: -
B27: 45693 | D27: Evi Diana Pertiwi | E27: Samsung | F27: Tab A9+5G | G27: -X216BGSMH | H27: - | I27: 128GB | J27: 8GB | K27: 11" | L27: - | M27: -
A30: KI | B30: 45139 | D30: Yeti Sumartiningsih | E30: OPPO | F30: Reno 8T | G30: 860443065272156 | H30: MediaTek Helio G99 | I30: 256GB | J30: 8GB | K30: 6.43" | L30: - | M30: - | N30: CRO
A31: MKS | B31: 45309 | D31: Biwa Murtada Djamaluddin | E31: Canon | F31: M200 | G31: 218073005764 | H31: - | I31: 16GB SD Card | J31: - | K31: - | L31: - | M31: -
A32: BLP | B32: 45370 | E32: Oppo | F32: Reno 10T | G32: 863753062187612 | H32: MediaTek Dimensi 7050 | I32: 256GB | J32: 8GB | K32: FHD+ (2412×1080) | L32: - | M32: -
B34: 45735 | D34: Suci Tri Puspitaningrum | E34: Apple | F34: #REF! | G34: KFWH4MFML6 | H34: - | I34: 64GB | K34: 10.2" | L34: - | M34: -

Sheet Copy of Form Serah Terima
B5: SERAH TERIMA FASILITAS PERUSAHAAN
C7: Yang bertandatangan dibawah ini :
C9: Nama | D9: : | E9: Afrizzal P. Pratama
C10: Jabatan | D10: : | E10: Departemen Head
C11: Departemen | D11: : | E11: IT
B13: Dalam hal ini bertindak untuk dan atas nama PT. Grahadhika Sarana Purnajati sesuai dengan kewenangan jabatannya yang selanjutnya disebut sebagai Pihak Pertama atau Yang Menyerahkan
C15: Nama | D15: : | E15: Ernie Ermaningsih
C16: Jabatan | D16: : | E16: ACM
C17: Departemen | D17: : | E17: Operational
C18: Alamat | D18: : | E18: Jl. M.H. Thamrin No.40, DR. Soetomo, Kec. Tegalsari, Surabaya, Jawa Timur 60264
C19: Dalam hal ini bertindak untuk dan atas nama dirinya sendiri sesuai dengan jabatan, yang selanjutnya disebut sebagai Pihak Kedua atau Yang Menerima.
B21: Bahwa untuk menunjang kinerja dari Pihak Kedua, maka dengan ini Pihak Pertama telah menyerahkan fasilitas perusahaan untuk digunakan oleh Pihak Kedua sesuai dengan data dibawah ini, antara Lain :
C22: 1. 1 (satu) Buah Laptop, dengan data spesifikasi sebagai berikut :
D24: a. | E24: Merek | F24: : | G24: Lenovo
D25: b. | E25: Type | F25: : | G25: IdeaPad 5 14ALC05
D26: c. | E26: Serial Number | F26: : | G26: MP27GVZW
D27: d. | E27: Processor | F27: : | G27: Ryzen 5 5500U
D28: e. | E28: Storage | F28: : | G28: SSD512GB
D29: f. | E29: RAM | F29: : | G29: 8GB
D30: g. | E30: Ukuran Layar | F30: : | G30: 14 INC
D31: f. | E31: Sistem Operasi | F31: : | G31: Win 11 Home SL
D32: g. | E32: Office | F32: : | G32: MS. Office 365 Bussiness
C36: 2. Software Terinstall, antara lain :
D38: a. | E38: Avast Free Antivirus
D39: b. | E39: Google Chrome
D40: c. | E40: Anydesk
D41: d. | E41: Microsoft Edge
D42: e. | E42: Office 365 Bussiness
D43: f. | E43: Tight Vnc
D44: e.
C45: 3. Kelengkapan tambahan, antara lain :
D47: a. | E47: Charger
D48: b. | E48: Tas
D49: c.
B53: Fasilitas tersebut diserahkan oleh Pihak Pertama kepada Pihak Kedua berkaitan dengan jabatannya sebagai ACM dengan dilakukannya serah terima ini maka berlaku beberapa hal yang harus diperhatikan, antara lain:
C55: 1. Bahwa Fasilitas perusahaan yang diterima oleh Pihak Kedua tidak diperbolehkan untuk dipindah tangankan dan atau dilakukan pengalihan fasilitas kepada orang lain selain dan tanpa adanya persetujuan atasan dan Persetujuan Pihak Pertama.
C57: 2. Bahwa Pihak Kedua bertanggung jawab secara penuh atas segala resiko yang terjadi dikarenakan timbulnya kerusakan dan atau kehilangan yang diakibatkan dari kelalaian Pihak Kedua yang dilakukan secara sengaja dan atau tidak sengaja selama penggunaan fasilitas tersebut. serta Pihak Kedua berkewajiban menanggung segala kerusakan secara pribadi seusai adanya pengecekan dari Pihak Pertama.
C59: 3. Bahwa Pihak Kedua bersedia dalam berjalannya waktu penggunaan fasilitas perusahaan tersebut, untuk dapat diperiksa dan atau dilakukannya audit terkait dengan isi dan dokumen yang ada dalam fasilitas tersebut.
C61: 4. Bahwa Pihak Kedua bertanggung Jawab secara penuh atas data, isi, konten dan dokumen yang berada didalam fasilitas perusahaan tersebut. Serta Pihak Kedua dilarang keras untuk menggunakan fasilitas perusahaan tersebut diluar kepentingan dan tujuan perusahaan yang dilakukan di dalam jam kerja maupun diluar jam kerja.
C63: 5. Apabila Pihak Kedua sudah tidak bekerja kembali dan atau mengundurkan diri. maka Pihak Kedua berkewajiban mengembalikan fasiltas perusahaan tersebut dalam keadaan baik sebagaimana mestinya.
...
